<?xml version="1.0" encoding="UTF-8"?>
<testng-results skipped="0" failed="1" ignored="0" total="1" passed="0">
  <reporter-output>
  </reporter-output>
  <suite name="Suite" duration-ms="17968" started-at="2021-03-26T12:43:41Z" finished-at="2021-03-26T12:43:59Z">
    <groups>
    </groups>
    <test name="Test" duration-ms="17968" started-at="2021-03-26T12:43:41Z" finished-at="2021-03-26T12:43:59Z">
      <class name="com.inetbanking.testcases.TC_AddCustomer_003">
        <test-method status="PASS" signature="setup(java.lang.String)[pri:0, instance:com.inetbanking.testcases.TC_AddCustomer_003@53b32d7]" name="setup" is-config="true" duration-ms="7284" started-at="2021-03-26T12:43:41Z" finished-at="2021-03-26T12:43:48Z">
          <params>
            <param index="0">
              <value>
                <![CDATA[chrome]]>
              </value>
            </param>
          </params>
          <reporter-output>
          </reporter-output>
        </test-method> <!-- setup -->
        <test-method status="FAIL" signature="addCutomer()[pri:0, instance:com.inetbanking.testcases.TC_AddCustomer_003@53b32d7]" name="addCutomer" duration-ms="9210" started-at="2021-03-26T12:43:48Z" finished-at="2021-03-26T12:43:57Z">
          <exception class="java.lang.AssertionError">
            <message>
              <![CDATA[expected [true] but found [false]]]>
            </message>
            <full-stacktrace>
              <![CDATA[java.lang.AssertionError: expected [true] but found [false]
at org.testng.Assert.fail(Assert.java:96)
at org.testng.Assert.failNotEquals(Assert.java:776)
at org.testng.Assert.assertTrue(Assert.java:44)
at org.testng.Assert.assertTrue(Assert.java:54)
at com.inetbanking.testcases.TC_AddCustomer_003.addCutomer(TC_AddCustomer_003.java:50)
at sun.reflect.NativeMethodAccessorImpl.invoke0(Native Method)
at sun.reflect.NativeMethodAccessorImpl.invoke(Unknown Source)
at sun.reflect.DelegatingMethodAccessorImpl.invoke(Unknown Source)
at java.lang.reflect.Method.invoke(Unknown Source)
at org.testng.internal.MethodInvocationHelper.invokeMethod(MethodInvocationHelper.java:124)
at org.testng.internal.Invoker.invokeMethod(Invoker.java:583)
at org.testng.internal.Invoker.invokeTestMethod(Invoker.java:719)
at org.testng.internal.Invoker.invokeTestMethods(Invoker.java:989)
at org.testng.internal.TestMethodWorker.invokeTestMethods(TestMethodWorker.java:125)
at org.testng.internal.TestMethodWorker.run(TestMethodWorker.java:109)
at org.testng.TestRunner.privateRun(TestRunner.java:648)
at org.testng.TestRunner.run(TestRunner.java:505)
at org.testng.SuiteRunner.runTest(SuiteRunner.java:455)
at org.testng.SuiteRunner.runSequentially(SuiteRunner.java:450)
at org.testng.SuiteRunner.privateRun(SuiteRunner.java:415)
at org.testng.SuiteRunner.run(SuiteRunner.java:364)
at org.testng.SuiteRunnerWorker.runSuite(SuiteRunnerWorker.java:52)
at org.testng.SuiteRunnerWorker.run(SuiteRunnerWorker.java:84)
at org.testng.TestNG.runSuitesSequentially(TestNG.java:1208)
at org.testng.TestNG.runSuitesLocally(TestNG.java:1137)
at org.testng.TestNG.runSuites(TestNG.java:1049)
at org.testng.TestNG.run(TestNG.java:1017)
at org.testng.remote.AbstractRemoteTestNG.run(AbstractRemoteTestNG.java:115)
at org.testng.remote.RemoteTestNG.initAndRun(RemoteTestNG.java:251)
at org.testng.remote.RemoteTestNG.main(RemoteTestNG.java:77)
]]>
            </full-stacktrace>
          </exception> <!-- java.lang.AssertionError -->
          <reporter-output>
          </reporter-output>
        </test-method> <!-- addCutomer -->
        <test-method status="PASS" signature="tearDown()[pri:0, instance:com.inetbanking.testcases.TC_AddCustomer_003@53b32d7]" name="tearDown" is-config="true" duration-ms="1210" started-at="2021-03-26T12:43:57Z" finished-at="2021-03-26T12:43:59Z">
          <reporter-output>
          </reporter-output>
        </test-method> <!-- tearDown -->
      </class> <!-- com.inetbanking.testcases.TC_AddCustomer_003 -->
    </test> <!-- Test -->
  </suite> <!-- Suite -->
</testng-results>
